Workbook

Sheet Build Priority
A1: Build Priority
A2: Iron Raider goal: all five at gear tier 20 for Omega tower floors. Lower number means build first. Change Priority or Status anytime and sort by Priority. Blank yellow cells are details to fill in from the game.
A4: Priority | B4: Character | C4: Team | D4: Level | E4: Gear tier | F4: Iso-8 | G4: Why build | H4: Next upgrade | I4: Event points | J4: Main cost | K4: Status | L4: Notes
A5: 1 | B5: Iron Monger | C5: Iron Raiders | D5: 85 | E5: 1 | F5: T3 L3 | G5: Iron Raider tower floors, raids | H5: 5 basic raid runs; raise abilities from level 1; gear up with surplus | I5: 40000000 | J5: Raid tickets, ability materials, gold | K5: In progress | L5: Level 85 and Iso-8 done Oct 11. Goal: gear tier 20 for Omega
A6: 2 | B6: Ulysses Klaue | C6: Iron Raiders | D6: 85 | E6: 1 | F6: T3 L3 | G6: Iron Raider tower floors, raids | H6: Raise abilities from level 1; gear up with surplus to his level cap | I6: 0 | J6: Ability materials, gold | K6: Not started | L6: Goal: gear tier 20 for Omega. Needs level 95+ for crimson-tier gear
A7: 3 | B7: Whiplash | C7: Iron Raiders | D7: 100 | E7: 19 | F7: T3 L3 | G7: Strongest Iron Raider | H7: Level 101, then gear tier 20 | I7: 20000000 | J7: Gold, training; crimson for tier 20 | K7: Not started | L7: One tier from the Omega goal of gear tier 20
A8: 4 | B8: Yellowjacket | C8: Iron Raiders | D8: 95 | E8: 18 | F8: T3 L3 | G8: Iron Raider tower floors, raids | H8: Level 101, then gear tier 19 and 20 | I8: 3000000 | J8: Gold, training | K8: Not started | L8: Two tiers from the Omega goal of gear tier 20
A9: 5 | B9: Crossbones | C9: Iron Raiders | D9: 85 | E9: 7 | F9: T3 L3 | G9: Fifth Iron Raider, needed for a full team | H9: Level up, abilities, Iso-8 to T3 L3 for raids | I9: 15000000 | J9: Gear and abilities | K9: In progress | L9: Level 85 and Iso-8 done Oct 11. Goal: gear tier 20 for Omega
A10: 6 | B10: Hulk | C10: Amazing Avengers | D10: 105 | E10: 20 | F10: T3 L5 | G10: Main team; next milestones upgrade him | H10: Gear tier 21 | I10: 150000000 | J10: Gold and gear | K10: In progress | L10: T3 L5 done Oct 11, T4 matrix unlocked. Holding orange ions for now
A11: 7 | B11: Spider-Man | C11: Amazing Avengers | D11: 105 | E11: 20 | F11: T3 L5 | G11: Main team; Diamond 4 at milestone 47 | H11: Gear tier 21 | I11: 150000000 | J11: Gold and gear | K11: In progress | L11: T3 L5 done Oct 12, T4 matrix unlocked. 3 diamonds
A12: 8 | B12: Blade (Mighty) | C12: Amazing Avengers | D12: 105 | F12: T3 L4 | G12: Main team; strongest tower character | H12: Iso-8 to T3 L5 | I12: 17000000 | J12: Purple ions | K12: Not started | L12: Only if Iso Fest ions come through
A13: 9 | B13: Spider-Woman (Julia) | C13: Amazing Avengers | D13: 105 | E13: 20 | F13: T3 L4 | G13: Main team | H13: Iso-8 to T3 L5 | I13: 17000000 | J13: Purple ions | K13: Not started | L13: 5 red stars, 104 of 200 shards. Needs ion 1 from Founding Force
A14: 10 | B14: Rachel Cole-Alves | C14: Amazing Avengers | F14: T3 L4 | G14: Main team | H14: Iso-8 to T3 L5 | I14: 17000000 | J14: Purple ions | K14: Not started | L14: 5 yellow stars. Only if Iso Fest ions come through
A15: 11 | B15: Wasp (Janet) | C15: Pym Tech | D15: 105 | E15: 20 | F15: T3 L5 | G15: Founding Force and Designed to Sting run 6 more weeks | H15: Watch for shards from those events | I15: 0 | K15: In progress | L15: 5 red stars, 80 of 200 shards. Keep some resources in reserve
A16: 11 | B16: Jocasta | C16: A.I. Avengers | D16: 1 | E16: 1 | G16: Blitz tasks in Iron Vengeance | H16: Blitz twice with her for 80M points | I16: 80000000 | J16: Power cores for more shards | K16: In progress | L16: Unlocked Oct 12, 1 of 55 shards to next star. Milestone 48 gives her 7 red stars
A17: 12 | B17: Doctor Strange | C17: Astral | D17: 100 | G17: Cheap event points only | H17: Level 101 | I17: 3000000 | J17: Gold, training | K17: Not started | L17: Only with leftover resources
A18: 13 | B18: Ancient One | C18: Astral | D18: 80 | F18: T3 L4 | H18: Hold | I18: 0 | K18: Not started | L18: Team is outdated. Play Astral events for their rewards
A19: 13 | B19: Moondragon | C19: Astral | D19: 60 | H19: Hold | I19: 0 | K19: Not started
A20: 13 | B20: Emma Frost (X-Men) | C20: Astral | D20: 105 | F20: T3 L4 | H20: Hold | I20: 0 | K20: Not started
A21: 13 | B21: Shadow King | C21: Astral | D21: 105 | F21: T3 L4 | H21: Hold | I21: 0 | K21: Not started | L21: Maxed red stars
A29: Iso Fest characters, Professor Xavier, Knull, Maestro and Spider-Man (Superior), aren't listed yet. Add them once you know whether to build them.

Sheet Tower Roster
A1: Tower Challenger III Roster
A2: Characters with the Tower Challenger III trait for the Kyln tower. Sorted by power. Yellow cells are yours to fill in: assign teams and mark who to focus on.
A4: Character | B4: Level | C4: Power | D4: Stars or diamonds | E4: Ability levels | F4: Also useful for | G4: Tower team | H4: Focus | I4: Notes
A5: Blade (Mighty) | B5: 105 | C5: 1739574 | D5: 1 diamond | E5: 7 6 7 4 | F5: Amazing Avengers
A6: Hobgoblin | B6: 105 | C6: 1702227 | D6: 3 diamonds | E6: 6 7 6 5
A7: Silver Surfer (Breaker) | B7: 105 | C7: 1663516 | D7: 6 red stars | E7: 7 7 7 5
A8: Superior Spider-Man | B8: 105 | C8: 1649971 | D8: 2 diamonds | E8: 7 7 6 5 | F8: Iso Fest | I8: Iso Fest gives him Diamonds 1 to 5
A9: Scorpion | B9: 105 | C9: 1461088 | D9: 3 diamonds | E9: 6 6 6 5
A10: Ikaris | B10: 100 | C10: 1401716 | D10: 2 diamonds | E10: 7 7 7 4
A11: Sersi | B11: 100 | C11: 1341960 | D11: 2 diamonds | E11: 7 7 7 5
A12: Storm (Mighty) | B12: 105 | C12: 1322529 | D12: 5 red stars | E12: 7 7 7 5
A13: Lady Bullseye | B13: 105 | C13: 1238262 | D13: 1 diamond | E13: 6 6 6 5
A14: Kingo | B14: 105 | C14: 1095153 | D14: Red stars, 13 of 300 shards | E14: 6 6 6 4
A15: Super Skrull | B15: 103 | C15: 1062491 | D15: 3 diamonds | E15: 7 7 7 5
A16: Gilgamesh | B16: 105 | C16: 1039168 | D16: 4 yellow stars | E16: 6 7 7 5
A17: Scorpion (Breaker) | B17: 104 | C17: 993737 | D17: 6 red stars | E17: 6 6 6 4
A18: Sword Master | B18: 100 | C18: 946060 | D18: 2 diamonds | E18: 6 6 6 5
A19: Thena | B19: 105 | C19: 900021 | D19: 4 red stars | E19: 6 6 6 4
A20: Steel Serpent | B20: 100 | C20: 889970 | D20: 2 diamonds | E20: 6 6 6 4
... A22: Iron Fist (WWII) | B22: 100 | C22: 847430 | D22: 1 diamond | E22: 6 6 6 5
A23: Whiplash | B23: 100 | C23: 827833 | D23: 6 red stars | E23: 6 6 6 4 | F23: Iron Raiders | I23: Level 101 and gear tier 20 planned
A24: Nightcrawler | B24: 101 | C24: 818549 | D24: 2 diamonds | E24: 7 7 7 5
A25: Kestrel | B25: 103 | C25: 787184 | D25: 2 diamonds | E25: 7 7 7 5
A26: Sunspot | B26: 96 | C26: 736328 | D26: 3 diamonds | E26: 6 6 6 5
A27: Yellowjacket | B27: 95 | C27: 731016 | D27: 2 diamonds | E27: 6 6 6 4 | F27: Iron Raiders | I27: Level 101 planned
A28: Deathpool | B28: 95 | C28: 573611 | D28: 4 diamonds | E28: 6 6 6 4
A29: Dormammu | B29: 100 | C29: 556594 | D29: 7 stars, maxed | E29: 7 7 7 5
A30: Northstar | B30: 95 | C30: 427837 | D30: 1 diamond | E30: 6 6 6 4
A31: Sunfire | B31: 90 | C31: 334475 | D31: 3 diamonds | E31: 6 6 6 4
A32: Dagger | B32: 95 | C32: 309062 | D32: 7 red stars, maxed | E32: 6 6 6 4
A33: Sasquatch | B33: 90 | C33: 305523 | D33: 1 diamond | E33: 6 6 6 5
A34: Cloak | B34: 95 | C34: 302615 | D34: 7 red stars, maxed | E34: 6 6 6 4
A35: Darkhawk | B35: 90 | C35: 269160 | D35: 1 diamond | E35: 6 6 6 4
A36: Ultron | B36: 80 | C36: 250273 | D36: 7 stars, maxed | E36: 7 7 7 5
A37: Archangel | B37: 90 | C37: 245993 | D37: 7 stars, maxed | E37: 7 7 8 6
A38: Vision | B38: 75 | C38: 228686 | D38: 7 red stars, maxed | E38: 6 6 6 4
A39: Ironheart (MKII) | B39: 75 | C39: 144778 | D39: 7 red stars, maxed | E39: 6 6 6 4
A40: Ulysses Klaue | B40: 85 | C40: 33212 | D40: 4 red stars | E40: 1 1, two locked | F40: Iron Raiders | I40: Abilities at level 1
A41: Crossbones | B41: 39 | C41: 32994 | D41: 2 diamonds | E41: 4 4 3 2 | F41: Iron Raiders
A42: Iron Monger | B42: 85 | C42: 26827 | D42: 3 red stars | E42: 1 1, two locked | F42: Iron Raiders | I42: Abilities at level 1
...

Sheet Kyln Tower
A1: Kyln: Code Blazes
A2: Milestones give Human Torch (Jim) shards. Log each floor attempt below; team power fills in from the Tower Roster. Yellow cells are yours to edit.
A4: Ends (approx.) | B4: 46332.708
A5: High score | B5: 400
A6: Next milestone | B6: =IFERROR(INDEX(A10:A29,MATCH(TRUE(),INDEX(B10:B29>B5,0),0)),"All done") -> 2
A7: Points to next | B7: =IFERROR(INDEX(B10:B29,MATCH(TRUE(),INDEX(B10:B29>B5,0),0))-B5,0) -> 400
A9: Milestone | B9: Score needed | C9: Human Torch (Jim) | D9: Reward | E9: Useful for | F9: Status
A10: 1 | B10: 400 | C10: 10 shards | D10: 120K purple orb item | F10: Claimed
A11: 2 | B11: 800 | C11: 15 shards | D11: To 1 red star | F11: Not claimed
A12: 3 | B12: 1200 | C12: 20 shards | D12: To 2 red stars | F12: Not claimed
A13: 4 | B13: 1600 | C13: 25 shards | D13: 200K teal orb item | F13: Not claimed
A14: 5 | B14: 2000 | C14: 30 shards | D14: To 3 red stars | F14: Not claimed
A15: 6 | B15: 2400 | C15: 35 shards | D15: 500 orange training | E15: Leveling, Iron Vengeance level tasks | F15: Not claimed
A16: 7 | B16: 2800 | C16: 40 shards | D16: 200K Red orb, unidentified | F16: Not claimed
A17: 8 | B17: 3200 | C17: 45 shards | D17: To 4 red stars | F17: Not claimed
A18: 9 | B18: 3600 | C18: 50 shards | D18: 300K Red orb, unidentified | F18: Not claimed
A19: 10 | B19: 4000 | C19: 55 shards | D19: To 5 red stars | F19: Not claimed
A20: 11 | B20: 4400 | C20: 60 shards | D20: 500 orange training | E20: Leveling, Iron Vengeance level tasks | F20: Not claimed
A21: 12 | B21: 4800 | C21: 65 shards | D21: 40K Red gear item, possibly crimson | E21: Iron Raider gear if crimson | F21: Not claimed
A22: 13 | B22: 5200 | C22: 70 shards | D22: 1,000 orange training | E22: Leveling, Iron Vengeance level tasks | F22: Not claimed
A23: 14 | B23: 5600 | C23: 75 shards | D23: 50K Red gear item, possibly crimson | E23: Iron Raider gear if crimson | F23: Not claimed
A24: 15 | B24: 6000 | C24: 45 shards | D24: To 6 red stars | F24: Not claimed
A25: 16 | B25: 6400 | C25: 80 shards | D25: 2M purple ions | E25: Iso-8 upgrades; ion type from icon, confirm | F25: Not claimed
A26: 17 | B26: 6800 | C26: 90 shards | D26: 2.64M purple ions | E26: Iso-8 upgrades; ion type from icon, confirm | F26: Not claimed
A27: 18 | B27: 7200 | D27: To 7 red stars, plus 20K Red gear item, possibly crimson | F27: Not claimed
A28: 19 | B28: 7600 | D28: Diamond 1, plus 2.64M purple ions | E28: Iso-8 upgrades | F28: Not claimed
A29: 20 | B29: 8000 | D29: Diamond 2, plus 30K Red gear item, possibly crimson | F29: Not claimed
A31: Floor log
A32: Floor | B32: Difficulty | C32: Floor requirement | D32: Character 1 | E32: Character 2 | F32: Character 3 | G32: Character 4 | H32: Character 5 | I32: Team power | J32: Result | K32: Attempts | L32: Score earned | M32: Notes
A33: Cell 1 | D33: Lady Bullseye | E33: Sword Master | F33: Steel Serpent | G33: Iron Fist | H33: Iron Fist (WWII) | I33: =SUMIF('Tower Roster'!$A$5:$A$44,D33,'Tower Roster'!$C$5:$C$44)+SUMIF('Tower Roster'!$A$5:$A$44,E33,'Tower Roster'!$C$5:$C$44)+SUMIF('Tower Roster'!$A$5:$A$44,F33,'Tower Roster'!$C$5:$C$44)+SUMIF('Tower Roster'!$A$5:$A$44,G33,'Tower Roster'!$C$5:$C$44)+SUMIF('Tower Roster'!$A$5:$A$44,H33,'Tower Roster'!$C$5:$C$44) -> 4789170 | J33: Cleared | K33: 1 | L33: 400 | M33: Immortal Weapons
I34: =SUMIF('Tower Roster'!$A$5:$A$44,D34,'Tower Roster'!$C$5:$C$44)+SUMIF('Tower Roster'!$A$5:$A$44,E34,'Tower Roster'!$C$5:$C$44)+SUMIF('Tower Roster'!$A$5:$A$44,F34,'Tower Roster'!$C$5:$C$44)+SUMIF('Tower Roster'!$A$5:$A$44,G34,'Tower Roster'!$C$5:$C$44)+SUMIF('Tower Roster'!$A$5:$A$44,H34,'Tower Roster'!$C$5:$C$44) -> 0
I35: =SUMIF('Tower Roster'!$A$5:$A$44,D35,'Tower Roster'!$C$5:$C$44)+SUMIF('Tower Roster'!$A$5:$A$44,E35,'Tower Roster'!$C$5:$C$44)+SUMIF('Tower Roster'!$A$5:$A$44,F35,'Tower Roster'!$C$5:$C$44)+SUMIF('Tower Roster'!$A$5:$A$44,G35,'Tower Roster'!$C$5:$C$44)+SUMIF('Tower Roster'!$A$5:$A$44,H35,'Tower Roster'!$C$5:$C$44) -> 0
I36: =SUMIF('Tower Roster'!$A$5:$A$44,D36,'Tower Roster'!$C$5:$C$44)+SUMIF('Tower Roster'!$A$5:$A$44,E36,'Tower Roster'!$C$5:$C$44)+SUMIF('Tower Roster'!$A$5:$A$44,F36,'Tower Roster'!$C$5:$C$44)+SUMIF('Tower Roster'!$A$5:$A$44,G36,'Tower Roster'!$C$5:$C$44)+SUMIF('Tower Roster'!$A$5:$A$44,H36,'Tower Roster'!$C$5:$C$44) -> 0
I37: =SUMIF('Tower Roster'!$A$5:$A$44,D37,'Tower Roster'!$C$5:$C$44)+SUMIF('Tower Roster'!$A$5:$A$44,E37,'Tower Roster'!$C$5:$C$44)+SUMIF('Tower Roster'!$A$5:$A$44,F37,'Tower Roster'!$C$5:$C$44)+SUMIF('Tower Roster'!$A$5:$A$44,G37,'Tower Roster'!$C$5:$C$44)+SUMIF('Tower Roster'!$A$5:$A$44,H37,'Tower Roster'!$C$5:$C$44) -> 0
I38: =SUMIF('Tower Roster'!$A$5:$A$44,D38,'Tower Roster'!$C$5:$C$44)+SUMIF('Tower Roster'!$A$5:$A$44,E38,'Tower Roster'!$C$5:$C$44)+SUMIF('Tower Roster'!$A$5:$A$44,F38,'Tower Roster'!$C$5:$C$44)+SUMIF('Tower Roster'!$A$5:$A$44,G38,'Tower Roster'!$C$5:$C$44)+SUMIF('Tower Roster'!$A$5:$A$44,H38,'Tower Roster'!$C$5:$C$44) -> 0
I39: =SUMIF('Tower Roster'!$A$5:$A$44,D39,'Tower Roster'!$C$5:$C$44)+SUMIF('Tower Roster'!$A$5:$A$44,E39,'Tower Roster'!$C$5:$C$44)+SUMIF('Tower Roster'!$A$5:$A$44,F39,'Tower Roster'!$C$5:$C$44)+SUMIF('Tower Roster'!$A$5:$A$44,G39,'Tower Roster'!$C$5:$C$44)+SUMIF('Tower Roster'!$A$5:$A$44,H39,'Tower Roster'!$C$5:$C$44) -> 0
I40: =SUMIF('Tower Roster'!$A$5:$A$44,D40,'Tower Roster'!$C$5:$C$44)+SUMIF('Tower Roster'!$A$5:$A$44,E40,'Tower Roster'!$C$5:$C$44)+SUMIF('Tower Roster'!$A$5:$A$44,F40,'Tower Roster'!$C$5:$C$44)+SUMIF('Tower Roster'!$A$5:$A$44,G40,'Tower Roster'!$C$5:$C$44)+SUMIF('Tower Roster'!$A$5:$A$44,H40,'Tower Roster'!$C$5:$C$44) -> 0
I41: =SUMIF('Tower Roster'!$A$5:$A$44,D41,'Tower Roster'!$C$5:$C$44)+SUMIF('Tower Roster'!$A$5:$A$44,E41,'Tower Roster'!$C$5:$C$44)+SUMIF('Tower Roster'!$A$5:$A$44,F41,'Tower Roster'!$C$5:$C$44)+SUMIF('Tower Roster'!$A$5:$A$44,G41,'Tower Roster'!$C$5:$C$44)+SUMIF('Tower Roster'!$A$5:$A$44,H41,'Tower Roster'!$C$5:$C$44) -> 0
I42: =SUMIF('Tower Roster'!$A$5:$A$44,D42,'Tower Roster'!$C$5:$C$44)+SUMIF('Tower Roster'!$A$5:$A$44,E42,'Tower Roster'!$C$5:$C$44)+SUMIF('Tower Roster'!$A$5:$A$44,F42,'Tower Roster'!$C$5:$C$44)+SUMIF('Tower Roster'!$A$5:$A$44,G42,'Tower Roster'!$C$5:$C$44)+SUMIF('Tower Roster'!$A$5:$A$44,H42,'Tower Roster'!$C$5:$C$44) -> 0
I43: =SUMIF('Tower Roster'!$A$5:$A$44,D43,'Tower Roster'!$C$5:$C$44)+SUMIF('Tower Roster'!$A$5:$A$44,E43,'Tower Roster'!$C$5:$C$44)+SUMIF('Tower Roster'!$A$5:$A$44,F43,'Tower Roster'!$C$5:$C$44)+SUMIF('Tower Roster'!$A$5:$A$44,G43,'Tower Roster'!$C$5:$C$44)+SUMIF('Tower Roster'!$A$5:$A$44,H43,'Tower Roster'!$C$5:$C$44) -> 0
...

Sheet Iron Vengeance
A1: Iron Vengeance Milestone Tracker
A2: Update Current points as you play and set each Status from its dropdown. Data from your screenshots on Oct 10, 2026.
A4: Scoring | B4: Earn 5-Diamond Blade (Mighty)
A5: Ends (approx.) | B5: 46313.708
A6: Current points | B6: 666802650 | D6: Reachable with planned tasks | E6: =B6+Scoring!F51 -> 6024802650
A7: Milestones reached | B7: =SUMPRODUCT((B13:B76<>"")*(B13:B76<=B6))+SUMPRODUCT((B13:B76="")*(F13:F76="Claimed")) -> 46 | D7: Highest milestone that reaches | E7: =IFERROR(INDEX(A13:A76,MATCH(E6,B13:B76,1)),37) -> 64
A8: Next milestone | B8: =IFERROR(INDEX(A13:A76,MATCH(TRUE(),INDEX(B13:B76>B6,0),0)),"All done") -> 47 | D8: Ready to claim now | E8: =SUMPRODUCT((B13:B76<>"")*(B13:B76<=B6)*(F13:F76<>"Claimed")) -> 0
A9: Points to next | B9: =IFERROR(INDEX(E13:E76,MATCH(TRUE(),INDEX(B13:B76>B6,0),0)),0) -> 23197350
A10: Points to max | B10: =MAX(0,B76-B6) -> 3458197350
A11: Points per day for max | B11: =IFERROR(B10/MAX(B5-NOW(),0.01),0) -> 5.501686e+08
A12: Milestone | B12: Points needed | C12: Reward | D12: Notes | E12: Points to go | F12: Status
A13: 1 | C13: 45 Yellowjacket shards | E13: =IF(B13="","",MAX(0,B13-$B$6)) | F13: Claimed
A14: 2 | C14: 45 Crossbones shards | E14: =IF(B14="","",MAX(0,B14-$B$6)) | F14: Claimed
A15: 3 | C15: 45 Whiplash shards | E15: =IF(B15="","",MAX(0,B15-$B$6)) | F15: Claimed
A16: 4 | C16: 45 Ulysses Klaue shards | E16: =IF(B16="","",MAX(0,B16-$B$6)) | F16: Claimed
A17: 5 | C17: 45 Iron Monger shards | E17: =IF(B17="","",MAX(0,B17-$B$6)) | F17: Claimed
A18: 6 | C18: 45 Hulk shards | E18: =IF(B18="","",MAX(0,B18-$B$6)) | F18: Claimed
A19: 7 | C19: 45 Spider-Man shards | E19: =IF(B19="","",MAX(0,B19-$B$6)) | F19: Claimed
A20: 8 | C20: 45 Spider-Woman (Julia) shards | E20: =IF(B20="","",MAX(0,B20-$B$6)) | F20: Claimed
A21: 9 | C21: 45 Rachel Cole-Alves shards | E21: =IF(B21="","",MAX(0,B21-$B$6)) | F21: Claimed
A22: 10 | C22: 45 Blade shards | E22: =IF(B22="","",MAX(0,B22-$B$6)) | F22: Claimed
A23: 11 | C23: Yellowjacket to 7 red stars | E23: =IF(B23="","",MAX(0,B23-$B$6)) | F23: Claimed
A24: 12 | C24: Crossbones to 7 red stars | E24: =IF(B24="","",MAX(0,B24-$B$6)) | F24: Claimed
... A41: 29 | C41: 55 Rachel Cole-Alves shards + 9,000 costume credits | E41: =IF(B41="","",MAX(0,B41-$B$6)) | F41: Claimed
A42: 30 | D42: No reward shown in game | E42: =IF(B42="","",MAX(0,B42-$B$6)) | F42: Claimed
A43: 31 | D43: No reward shown in game | E43: =IF(B43="","",MAX(0,B43-$B$6)) | F43: Claimed
A44: 32 | D44: No reward shown in game | E44: =IF(B44="","",MAX(0,B44-$B$6)) | F44: Claimed
A45: 33 | D45: No reward shown in game | E45: =IF(B45="","",MAX(0,B45-$B$6)) | F45: Claimed
A46: 34 | C46: Spider-Man Diamond 1 | E46: =IF(B46="","",MAX(0,B46-$B$6)) | F46: Claimed
A47: 35 | C47: Yellowjacket Diamond 2 | E47: =IF(B47="","",MAX(0,B47-$B$6)) | F47: Claimed
A48: 36 | C48: Crossbones Diamond 2 | E48: =IF(B48="","",MAX(0,B48-$B$6)) | F48: Claimed
A49: 37 | C49: Hulk Diamond 2 | E49: =IF(B49="","",MAX(0,B49-$B$6)) | F49: Claimed
A50: 38 | B50: 435000000 | C50: Spider-Man Diamond 2 | E50: =IF(B50="","",MAX(0,B50-$B$6)) -> 0 | F50: Claimed
A51: 39 | B51: 450000000 | C51: Yellowjacket Diamond 3 | E51: =IF(B51="","",MAX(0,B51-$B$6)) -> 0 | F51: Claimed
A52: 40 | B52: 480000000 | C52: Crossbones Diamond 3 | E52: =IF(B52="","",MAX(0,B52-$B$6)) -> 0 | F52: Claimed
A53: 41 | B53: 510000000 | C53: Whiplash Diamond 1 | D53: Bar and icon cut off, confirm in game | E53: =IF(B53="","",MAX(0,B53-$B$6)) -> 0 | F53: Claimed
A54: 42 | B54: 540000000 | C54: Ulysses Klaue Diamond 1 | E54: =IF(B54="","",MAX(0,B54-$B$6)) -> 0 | F54: Claimed
A55: 43 | B55: 570000000 | C55: Iron Monger Diamond 1 | E55: =IF(B55="","",MAX(0,B55-$B$6)) -> 0 | F55: Claimed
A56: 44 | B56: 600000000 | C56: Hulk Diamond 3 | E56: =IF(B56="","",MAX(0,B56-$B$6)) -> 0 | F56: Claimed
A57: 45 | B57: 630000000 | C57: Spider-Man Diamond 3 | E57: =IF(B57="","",MAX(0,B57-$B$6)) -> 0 | F57: Claimed
...

Sheet Scoring
A1: How to earn points
A2: Update Earned from the event info screen. Set Plan to No for tasks you can't do, and the summary adjusts.
A4: Type | B4: Task | C4: Points each | D4: Limit | E4: Earned | F4: Points left | G4: Times to max | H4: Times done | I4: Times left | J4: Plan
A5: Daily | B5: Daily Login | C5: 4000000 | D5: 40000000 | E5: 16000000 | F5: =IF(ISNUMBER(D5),MAX(0,D5-E5),0) -> 24000000 | G5: =IF(ISNUMBER(D5),ROUNDUP(D5/C5,0),"No limit") -> 10 | H5: =IFERROR(INT(E5/C5),0) -> 4 | I5: =IFERROR(ROUNDUP(F5/C5,0),0) -> 6 | J5: Yes
A6: Daily | B6: Complete All Clear daily mission | C6: 4000000 | D6: 40000000 | E6: 12000000 | F6: =IF(ISNUMBER(D6),MAX(0,D6-E6),0) -> 28000000 | G6: =IF(ISNUMBER(D6),ROUNDUP(D6/C6,0),"No limit") -> 10 | H6: =IFERROR(INT(E6/C6),0) -> 3 | I6: =IFERROR(ROUNDUP(F6/C6,0),0) -> 7 | J6: Yes
A7: Spend | B7: Spend 1 Gold | C7: 1 | D7: 1000000000 | E7: 52952650 | F7: =IF(ISNUMBER(D7),MAX(0,D7-E7),0) -> 947047350 | G7: =IF(ISNUMBER(D7),ROUNDUP(D7/C7,0),"No limit") -> 1000000000 | H7: =IFERROR(INT(E7/C7),0) -> 52952650 | I7: =IFERROR(ROUNDUP(F7/C7,0),0) -> 947047350 | J7: No
A8: Spend | B8: Spend 1 Power Core | C8: 4000 | D8: 1000000000 | E8: 34600000 | F8: =IF(ISNUMBER(D8),MAX(0,D8-E8),0) -> 965400000 | G8: =IF(ISNUMBER(D8),ROUNDUP(D8/C8,0),"No limit") -> 250000 | H8: =IFERROR(INT(E8/C8),0) -> 8650 | I8: =IFERROR(ROUNDUP(F8/C8,0),0) -> 241350 | J8: No
A9: Level | B9: Upgrade any character to level 101 | C9: 3000000 | D9: 15000000 | E9: 9000000 | F9: =IF(ISNUMBER(D9),MAX(0,D9-E9),0) -> 6000000 | G9: =IF(ISNUMBER(D9),ROUNDUP(D9/C9,0),"No limit") -> 5 | H9: =IFERROR(INT(E9/C9),0) -> 3 | I9: =IFERROR(ROUNDUP(F9/C9,0),0) -> 2 | J9: Yes
A10: Level | B10: Upgrade any character to level 110 | C10: 8000000 | D10: 40000000 | E10: 0 | F10: =IF(ISNUMBER(D10),MAX(0,D10-E10),0) -> 40000000 | G10: =IF(ISNUMBER(D10),ROUNDUP(D10/C10,0),"No limit") -> 5 | H10: =IFERROR(INT(E10/C10),0) -> 0 | I10: =IFERROR(ROUNDUP(F10/C10,0),0) -> 5 | J10: Yes
A11: Raid | B11: Alliance Raid with Blade (Mighty) | C11: 7000000 | D11: 35000000 | E11: 35000000 | F11: =IF(ISNUMBER(D11),MAX(0,D11-E11),0) -> 0 | G11: =IF(ISNUMBER(D11),ROUNDUP(D11/C11,0),"No limit") -> 5 | H11: =IFERROR(INT(E11/C11),0) -> 5 | I11: =IFERROR(ROUNDUP(F11/C11,0),0) -> 0 | J11: Yes
A12: Raid | B12: Alliance Raid with Blade (Mighty), 7 yellow stars, Gear Tier 20 | C12: 17000000 | D12: 85000000 | E12: 85000000 | F12: =IF(ISNUMBER(D12),MAX(0,D12-E12),0) -> 0 | G12: =IF(ISNUMBER(D12),ROUNDUP(D12/C12,0),"No limit") -> 5 | H12: =IFERROR(INT(E12/C12),0) -> 5 | I12: =IFERROR(ROUNDUP(F12/C12,0),0) -> 0 | J12: Yes
A13: Raid | B13: Alliance Raid with Spider-Woman (Julia) | C13: 7000000 | D13: 35000000 | E13: 35000000 | F13: =IF(ISNUMBER(D13),MAX(0,D13-E13),0) -> 0 | G13: =IF(ISNUMBER(D13),ROUNDUP(D13/C13,0),"No limit") -> 5 | H13: =IFERROR(INT(E13/C13),0) -> 5 | I13: =IFERROR(ROUNDUP(F13/C13,0),0) -> 0 | J13: Yes
A14: Raid | B14: Alliance Raid with Spider-Woman (Julia), 7 yellow stars, Gear Tier 20 | C14: 17000000 | D14: 85000000 | E14: 0 | F14: =IF(ISNUMBER(D14),MAX(0,D14-E14),0) -> 85000000 | G14: =IF(ISNUMBER(D14),ROUNDUP(D14/C14,0),"No limit") -> 5 | H14: =IFERROR(INT(E14/C14),0) -> 0 | I14: =IFERROR(ROUNDUP(F14/C14,0),0) -> 5 | J14: Yes
A15: Raid | B15: Alliance Raid with Rachel Cole-Alves | C15: 7000000 | D15: 35000000 | E15: 35000000 | F15: =IF(ISNUMBER(D15),MAX(0,D15-E15),0) -> 0 | G15: =IF(ISNUMBER(D15),ROUNDUP(D15/C15,0),"No limit") -> 5 | H15: =IFERROR(INT(E15/C15),0) -> 5 | I15: =IFERROR(ROUNDUP(F15/C15,0),0) -> 0 | J15: Yes
A16: Raid | B16: Alliance Raid with Rachel Cole-Alves, 7 yellow stars, Gear Tier 20 | C16: 17000000 | D16: 85000000 | E16: 0 | F16: =IF(ISNUMBER(D16),MAX(0,D16-E16),0) -> 85000000 | G16: =IF(ISNUMBER(D16),ROUNDUP(D16/C16,0),"No limit") -> 5 | H16: =IFERROR(INT(E16/C16),0) -> 0 | I16: =IFERROR(ROUNDUP(F16/C16,0),0) -> 5 | J16: Yes
... A46: Daily | B46: Web store free claim, Oct 12 onward | C46: 4500000 | D46: 27000000 | E46: 0 | F46: =IF(ISNUMBER(D46),MAX(0,D46-E46),0) -> 27000000 | G46: =IF(ISNUMBER(D46),ROUNDUP(D46/C46,0),"No limit") -> 6 | H46: =IFERROR(INT(E46/C46),0) -> 0 | I46: =IFERROR(ROUNDUP(F46/C46,0),0) -> 6 | J46: Yes
A47: Offers | B47: Milestone points from select offers, includes free claims so far | C47: 1 | D47: Unlimited | E47: 40250000 | F47: =IF(ISNUMBER(D47),MAX(0,D47-E47),0) -> 0 | G47: =IF(ISNUMBER(D47),ROUNDUP(D47/C47,0),"No limit") -> No limit | H47: =IFERROR(INT(E47/C47),0) -> 40250000 | I47: =IFERROR(ROUNDUP(F47/C47,0),0) -> 0 | J47: No
B49: Earned so far from listed tasks | E49: =SUM(E5:E47) -> 666802650
B50: Points left, all tasks | F50: =SUM(F5:F47) -> 7270447350
B51: Points left, tasks planned | F51: =SUMIF(J5:J47,"Yes",F5:F47) -> 5358000000
B52: One task, limit 100,000,000, was cut off in your screenshots and isn't listed.

Sheet Resources
A1: Resources
A2: Purple ions 1 to 3 follow the order on the Iso-8 screen, left to right. Update Current stock from the game. When something arrives, add it to your stock and set Received to Yes. Mark upgrades Done once finished.
A4: Summary | B4: Gold | C4: Purple ion 1 | D4: Purple ion 2 | E4: Purple ion 3 | F4: Blue training | G4: Purple training | H4: Orange training
A5: Current stock | B5: 12130000 | C5: 159500 | D5: 2590000 | E5: 13420000 | F5: 221 | G5: 869 | H5: 194
A6: Still coming | B6: =SUMIFS(B13:B76,$I$13:$I$76,"Yes",$J$13:$J$76,"No") -> 27050000 | C6: =SUMIFS(C13:C76,$I$13:$I$76,"Yes",$J$13:$J$76,"No") -> 3700000 | D6: =SUMIFS(D13:D76,$I$13:$I$76,"Yes",$J$13:$J$76,"No") -> 3886000 | E6: =SUMIFS(E13:E76,$I$13:$I$76,"Yes",$J$13:$J$76,"No") -> 3486000 | F6: =SUMIFS(F13:F76,$I$13:$I$76,"Yes",$J$13:$J$76,"No") -> 0 | G6: =SUMIFS(G13:G76,$I$13:$I$76,"Yes",$J$13:$J$76,"No") -> 100 | H6: =SUMIFS(H13:H76,$I$13:$I$76,"Yes",$J$13:$J$76,"No") -> 885
A7: Projected total | B7: =B5+B6 -> 39180000 | C7: =C5+C6 -> 3859500 | D7: =D5+D6 -> 6476000 | E7: =E5+E6 -> 16906000 | F7: =F5+F6 -> 221 | G7: =G5+G6 -> 969 | H7: =H5+H6 -> 1079
A8: Planned spending | B8: =SUMIF($J$80:$J$101,"Planned",B80:B101) -> 0 | C8: =SUMIF($J$80:$J$101,"Planned",C80:C101) -> 0 | D8: =SUMIF($J$80:$J$101,"Planned",D80:D101) -> 0 | E8: =SUMIF($J$80:$J$101,"Planned",E80:E101) -> 0 | F8: =SUMIF($J$80:$J$101,"Planned",F80:F101) -> 0 | G8: =SUMIF($J$80:$J$101,"Planned",G80:G101) -> 0 | H8: =SUMIF($J$80:$J$101,"Planned",H80:H101) -> 0
A9: Left after plan | B9: =B7-B8 -> 39180000 | C9: =C7-C8 -> 3859500 | D9: =D7-D8 -> 6476000 | E9: =E7-E8 -> 16906000 | F9: =F7-F8 -> 221 | G9: =G7-G8 -> 969 | H9: =H7-H8 -> 1079
A10: Red means that resource runs out before the plan is done. Yellow blanks are costs to check in game.
A11: Coming in
A12: Source | B12: Gold | C12: Purple ion 1 | D12: Purple ion 2 | E12: Purple ion 3 | F12: Blue training | G12: Purple training | H12: Orange training | I12: Count on it | J12: Received | K12: Notes
A13: Today's remaining optional objectives | B13: 100000 | C13: 0 | D13: 0 | E13: 0 | F13: 0 | G13: 0 | H13: 0 | I13: Yes | J13: Yes | K13: Raid battles objective
A14: Daily objectives, Oct 12 | B14: 1600000 | C14: 0 | D14: 0 | E14: 0 | F14: 0 | G14: 0 | H14: 0 | I14: Yes | J14: Yes | K14: All Clear plus optional objectives
A15: Daily objectives, Oct 13 | B15: 1600000 | C15: 0 | D15: 0 | E15: 0 | F15: 0 | G15: 0 | H15: 0 | I15: Yes | J15: No | K15: All Clear plus optional objectives
A16: Daily objectives, Oct 14 | B16: 1600000 | C16: 0 | D16: 0 | E16: 0 | F16: 0 | G16: 0 | H16: 0 | I16: Yes | J16: No | K16: All Clear plus optional objectives
A17: Daily objectives, Oct 15 | B17: 1600000 | C17: 0 | D17: 0 | E17: 0 | F17: 0 | G17: 0 | H17: 0 | I17: Yes | J17: No | K17: All Clear plus optional objectives
A18: Daily objectives, Oct 16 | B18: 1600000 | C18: 0 | D18: 0 | E18: 0 | F18: 0 | G18: 0 | H18: 0 | I18: Yes | J18: No | K18: All Clear plus optional objectives
A19: Daily objectives, Oct 17 | B19: 1600000 | C19: 0 | D19: 0 | E19: 0 | F19: 0 | G19: 0 | H19: 0 | I19: Yes | J19: No | K19: All Clear plus optional objectives
A20: Daily objectives, Oct 18 | B20: 1600000 | C20: 0 | D20: 0 | E20: 0 | F20: 0 | G20: 0 | H20: 0 | I20: Yes | J20: No | K20: All Clear plus optional objectives
A21: Calendar day 14 | B21: 100000 | C21: 0 | D21: 0 | E21: 0 | F21: 0 | G21: 0 | H21: 0 | I21: Yes | J21: No
A22: Calendar day 16 | B22: 200000 | C22: 0 | D22: 0 | E22: 0 | F22: 0 | G22: 0 | H22: 0 | I22: Yes | J22: No
A23: Calendar day 20 | B23: 0 | C23: 0 | D23: 0 | E23: 0 | F23: 0 | G23: 100 | H23: 0 | I23: Yes | J23: No | K23: Likely the last day of Iron Vengeance
A24: Astral Radiance milestone 2 | B24: 150000 | C24: 0 | D24: 0 | E24: 0 | F24: 0 | G24: 0 | H24: 15 | I24: Yes | J24: Yes
A25: Astral Radiance milestone 3 | B25: 150000 | C25: 0 | D25: 0 | E25: 0 | F25: 0 | G25: 0 | H25: 20 | I25: Yes | J25: Yes
A26: Astral Radiance milestone 4 | B26: 200000 | C26: 0 | D26: 0 | E26: 0 | F26: 0 | G26: 0 | H26: 25 | I26: Yes | J26: Yes
A27: Astral Radiance milestone 5 | B27: 250000 | C27: 0 | D27: 0 | E27: 0 | F27: 0 | G27: 0 | H27: 30 | I27: Yes | J27: Yes
A28: Astral Radiance milestone 6 | B28: 300000 | C28: 0 | D28: 0 | E28: 0 | F28: 0 | G28: 0 | H28: 40 | I28: Yes | J28: No
A29: Astral Radiance milestone 7 | B29: 350000 | C29: 0 | D29: 0 | E29: 0 | F29: 0 | G29: 0 | H29: 45 | I29: Yes | J29: No
A30: Battle pass level 86 | B30: 0 | C30: 0 | D30: 0 | E30: 0 | F30: 0 | G30: 0 | H30: 0 | I30: Yes | J30: No | K30: Claimed Oct 11, in current stock
A31: Battle pass level 87 | B31: 0 | C31: 0 | D31: 0 | E31: 0 | F31: 0 | G31: 0 | H31: 0 | I31: Yes | J31: No | K31: Claimed Oct 11, in current stock
A32: Battle pass level 88 | B32: 0 | C32: 0 | D32: 0 | E32: 0 | F32: 0 | G32: 0 | H32: 0 | I32: Yes | J32: No | K32: Claimed Oct 11, in current stock
A33: Battle pass level 95, premium | B33: 0 | C33: 0 | D33: 0 | E33: 0 | F33: 0 | G33: 0 | H33: 800 | I33: Yes | J33: No
A34: Battle pass level 97, premium | B34: 10000000 | C34: 0 | D34: 0 | E34: 0 | F34: 0 | G34: 0 | H34: 0 | I34: Yes | J34: No
A35: Battle pass level 97 | B35: 500000 | C35: 0 | D35: 0 | E35: 0 | F35: 0 | G35: 0 | H35: 0 | I35: Yes | J35: No
A36: Founding Force milestone 4 | B36: 0 | C36: 3000000 | D36: 3000000 | E36: 2600000 | F36: 0 | G36: 0 | H36: 0 | I36: Yes | J36: No | K36: Needs the battle pass level 100 token
A37: Iso Fest milestone 15 | B37: 0 | C37: 0 | D37: 0 | E37: 0 | F37: 0 | G37: 0 | H37: 0 | I37: Yes | J37: No | K37: Claimed Oct 11, in current stock
A38: Iso Fest milestone 16 | B38: 0 | C38: 950000 | D38: 0 | E38: 1900000 | F38: 0 | G38: 0 | H38: 0 | I38: Yes | J38: Yes | K38: Reached Oct 12, ready to claim
A39: Iso Fest milestone 17 | B39: 0 | C39: 0 | D39: 1400000 | E39: 1900000 | F39: 0 | G39: 0 | H39: 0 | I39: No | J39: No
A40: VisionQuest level 30 | B40: 0 | C40: 200000 | D40: 0 | E40: 0 | F40: 0 | G40: 0 | H40: 0 | I40: Yes | J40: No | K40: Expected about Oct 14. At level 15 now, +5 a day
A41: VisionQuest levels 35 and 40 | B41: 0 | C41: 0 | D41: 750000 | E41: 750000 | F41: 0 | G41: 0 | H41: 0 | I41: Yes | J41: No | K41: Expected about Oct 15 and 16. Ion types read from icons
...

Sheet Dailies
A1: Dailies
A2: Mark each task Done from the dropdown. Objectives reset around 12:30 AM Eastern.
A4: Task | B4: Type | C4: Gold | D4: Other reward | E4: Sun Oct 11 | F4: Mon Oct 12 | G4: Tue Oct 13 | H4: Wed Oct 14 | I4: Thu Oct 15 | J4: Fri Oct 16 | K4: Sat Oct 17 | L4: Sun Oct 18
A5: Daily objectives
A6: Play 3 Heroes Assemble missions | B6: Required | C6: 25000 | D6: 25 energy | E6: Done | F6: Done
A7: Play 3 Villains United missions | B7: Required | C7: 25000 | D7: 100 items, 30 energy | E7: Done | F7: Done
A8: Auto Win 3 missions | B8: Required | C8: 50000 | D8: 10 S.T.R.I.K.E. pass tokens | E8: Done | F8: Done
A9: Complete 2 Arena battles | B9: Required | C9: 50000 | D9: 30 energy, 10 S.T.R.I.K.E. pass tokens | E9: Done | F9: Done
A10: Compete in 2 Blitz battles | B10: Required | C10: 50000 | D10: 10 S.T.R.I.K.E. pass tokens | E10: Done | F10: Done
A11: Finish 10 campaign missions | B11: Required | C11: 25000 | D11: 10 S.T.R.I.K.E. pass tokens | E11: Done | F11: Done
A12: Play 3 Iso-8 missions | B12: Required | C12: 25000 | D12: 20 S.T.R.I.K.E. pass tokens | E12: Done | F12: Done
A13: Complete 2 challenges | B13: Required | C13: 25000 | D13: 10 S.T.R.I.K.E. pass tokens | E13: Done | F13: Done
A14: Open 2 orbs | B14: Required | C14: 50000 | D14: 10 energy. Gold orbs count | E14: Done | F14: Done
A15: Make 3 supply purchases | B15: Required | C15: 50000 | D15: 10 S.T.R.I.K.E. pass tokens | E15: Done | F15: Done
A16: All Clear | B16: Required | C16: 1000000 | D16: 50 S.T.R.I.K.E. pass tokens and two more items | E16: Done | F16: Done
A17: Compete in 2 raid battles | B17: Optional | C17: 100000 | D17: 60 S.T.R.I.K.E. pass tokens | F17: Done
A18: Spend 600 campaign energy | B18: Optional | C18: 25000 | D18: 30 S.T.R.I.K.E. pass tokens | E18: Done | F18: Done
A19: Spend 400 Iso-8 energy | B19: Optional | C19: 25000 | D19: 50 S.T.R.I.K.E. pass tokens | E19: Done | F19: Done
A20: Make 1 alliance donation | B20: Optional | C20: 75000 | D20: 40 S.T.R.I.K.E. pass tokens | E20: Done | F20: Done
A21: Daily challenges and rewards
A22: Free energy, 12 PM to 3 PM | B22: Energy | C22: 0 | D22: Spend on missions for gold orb fragments | E22: Done
A23: Free energy, 6 PM to 9 PM | B23: Energy | C23: 0 | D23: Spend on missions for gold orb fragments
A24: Free energy, 9 PM to midnight | B24: Energy | C24: 0 | D24: Spend on missions for gold orb fragments
A25: Gold Rush, when available | B25: Challenge | C25: 900000 | D25: About 2,700 ability materials | E25: Done | F25: Done
A26: Training Day, when available | B26: Challenge | C26: 0 | D26: 30 purple and 90 orange training | E26: Done
A27: Collect monthly login calendar | B27: Login | C27: 0 | D27: Varies by day
A28: Battle pass objectives, about 2 levels | B28: Battle pass | C28: 0 | D28: Aim for level 100 by Oct 17
A29: Events
A30: Iron Vengeance: login and All Clear | B30: Event | C30: 0 | D30: 8 million points, automatic with All Clear
A31: Iron Vengeance: Iron Monger raid | B31: Event | C31: 0 | D31: 8 million points each, 5 total
A32: Iron Vengeance: Yellowjacket, Whiplash, Klaue raids | B32: Event | C32: 0 | D32: Until their limits are full
A33: Daily Web Reward, web store | B33: Web store | C33: 0 | D33: 100 campaign and 50 Iso-8 energy; enough fragments for one training orb and one energy orb | E33: Done
A34: VisionQuest: spend 10 surge energy in A.I. Avengers campaign | B34: Event | C34: 0 | D34: 5 levels. Resets about 6:40 PM
A35: Iron Vengeance: free web store milestone points | B35: Web store | C35: 0 | D35: Claim daily in the web store
A36: Iso Fest: free web store milestone points | B36: Web store | C36: 0 | D36: Claim daily in the web store
A37: Astral Radiance: Shadow King battle | B37: Event | C37: 0 | D37: 1,500 points each, 7 total
A38: Astral Radiance: Astral battles, about 5 | B38: Event | C38: 0 | D38: 900 points each, 35 total
A40: Gold collected | E40: =SUMPRODUCT(($C$5:$C$38)*(E5:E38="Done")) -> 2400000 | F40: =SUMPRODUCT(($C$5:$C$38)*(F5:F38="Done")) -> 2500000 | G40: =SUMPRODUCT(($C$5:$C$38)*(G5:G38="Done")) -> 0 | H40: =SUMPRODUCT(($C$5:$C$38)*(H5:H38="Done")) -> 0 | I40: =SUMPRODUCT(($C$5:$C$38)*(I5:I38="Done")) -> 0 | J40: =SUMPRODUCT(($C$5:$C$38)*(J5:J38="Done")) -> 0 | K40: =SUMPRODUCT(($C$5:$C$38)*(K5:K38="Done")) -> 0 | L40: =SUMPRODUCT(($C$5:$C$38)*(L5:L38="Done")) -> 0
A41: Objectives done, required | E41: =COUNTIFS($B$5:$B$38,"Required",E5:E38,"Done")&" of 11" -> 11 of 11 | F41: =COUNTIFS($B$5:$B$38,"Required",F5:F38,"Done")&" of 11" -> 11 of 11 | G41: =COUNTIFS($B$5:$B$38,"Required",G5:G38,"Done")&" of 11" -> 0 of 11 | H41: =COUNTIFS($B$5:$B$38,"Required",H5:H38,"Done")&" of 11" -> 0 of 11 | I41: =COUNTIFS($B$5:$B$38,"Required",I5:I38,"Done")&" of 11" -> 0 of 11 | J41: =COUNTIFS($B$5:$B$38,"Required",J5:J38,"Done")&" of 11" -> 0 of 11 | K41: =COUNTIFS($B$5:$B$38,"Required",K5:K38,"Done")&" of 11" -> 0 of 11 | L41: =COUNTIFS($B$5:$B$38,"Required",L5:L38,"Done")&" of 11" -> 0 of 11
A43: Oct 11 and Oct 12 are filled in from your screenshots. The calendar and battle pass rows are left for you.

Sheet Iso Fest
A1: Iso Fest Milestones
A2: Update Current points and set each Status from its dropdown. Ion columns follow the order on the Iso-8 screen, left to right. Data from your screenshots on Oct 11, 2026.
A4: Scoring | B4: Earn 5-Diamond Professor Xavier | D4: Purple ions still to claim
A5: Ends (approx.) | B5: 46313.708 | E5: Ion 1 | F5: Ion 2 | G5: Ion 3
A6: Current points | B6: 330153995 | D6: Up to target milestone | E6: =SUMPRODUCT((A13:A54<=$B$9)*(H13:H54<>"Claimed")*E13:E54) -> 1300000 | F6: =SUMPRODUCT((A13:A54<=$B$9)*(H13:H54<>"Claimed")*F13:F54) -> 4200000 | G6: =SUMPRODUCT((A13:A54<=$B$9)*(H13:H54<>"Claimed")*G13:G54) -> 5700000
A7: Next milestone | B7: =IFERROR(INDEX(A13:A54,MATCH(TRUE(),INDEX(B13:B54>B6,0),0)),"All done") -> 17 | D7: Ready to claim now | E7: =SUMPRODUCT((B13:B54<>"")*(B13:B54<=$B$6)*(H13:H54<>"Claimed")*E13:E54) -> 0 | F7: =SUMPRODUCT((B13:B54<>"")*(B13:B54<=$B$6)*(H13:H54<>"Claimed")*F13:F54) -> 0 | G7: =SUMPRODUCT((B13:B54<>"")*(B13:B54<=$B$6)*(H13:H54<>"Claimed")*G13:G54) -> 0
A8: Points to next | B8: =IFERROR(INDEX(I13:I54,MATCH(TRUE(),INDEX(B13:B54>B6,0),0)),0) -> 19846005
A9: Target milestone | B9: 20
A10: Points to target | B10: =MAX(0,INDEX(B13:B54,B9)-B6) -> 94846005
A11: Points per day for target | B11: =IFERROR(B10/MAX(B5-NOW(),0.01),0) -> 15089160
A12: Milestone | B12: Points needed | C12: Character reward | D12: Other reward | E12: Ion 1 | F12: Ion 2 | G12: Ion 3 | H12: Status | I12: Points to go
A13: 1 | D13: 200K blue, 800K green nuggets | E13: 0 | F13: 0 | G13: 0 | H13: Claimed | I13: =IF(B13="","",MAX(0,B13-$B$6))
A14: 2 | D14: 600K blue nuggets | E14: 0 | F14: 0 | G14: 0 | H14: Claimed | I14: =IF(B14="","",MAX(0,B14-$B$6))
A15: 3 | D15: 400K blue nuggets; 1M, 1M, 1.72M blue ions | E15: 0 | F15: 0 | G15: 0 | H15: Claimed | I15: =IF(B15="","",MAX(0,B15-$B$6))
A16: 4 | D16: 400K blue nuggets; 1M, 1M, 1.72M blue ions | E16: 0 | F16: 0 | G16: 0 | H16: Claimed | I16: =IF(B16="","",MAX(0,B16-$B$6))
A17: 5 | C17: Knull to 1 red star | D17: 1M, 1M blue ions; 400K blue nuggets | E17: 0 | F17: 0 | G17: 0 | H17: Claimed | I17: =IF(B17="","",MAX(0,B17-$B$6))
A18: 6 | C18: Professor Xavier to 1 red star | D18: 1M, 1M, 3.45M blue ions | E18: 0 | F18: 0 | G18: 0 | H18: Claimed | I18: =IF(B18="","",MAX(0,B18-$B$6))
A19: 7 | C19: Maestro to 1 red star | D19: 2M, 1M blue ions; 450K blue nuggets | E19: 0 | F19: 0 | G19: 0 | H19: Claimed | I19: =IF(B19="","",MAX(0,B19-$B$6))
A20: 8 | C20: Knull to 2 red stars | D20: 2M, 1M, 3.45M blue ions | E20: 0 | F20: 0 | G20: 0 | H20: Claimed | I20: =IF(B20="","",MAX(0,B20-$B$6))
A21: 9 | C21: Professor Xavier to 2 red stars | D21: 2M, 2M, 3.45M blue ions | E21: 0 | F21: 0 | G21: 0 | H21: Claimed | I21: =IF(B21="","",MAX(0,B21-$B$6))
A22: 10 | C22: Maestro to 2 red stars | D22: 1 item; 2M, 3.45M blue ions | E22: 0 | F22: 0 | G22: 0 | H22: Claimed | I22: =IF(B22="","",MAX(0,B22-$B$6))
A23: 11 | D23: 100K purple nuggets | E23: 900000 | F23: 1300000 | G23: 1900000 | H23: Claimed | I23: =IF(B23="","",MAX(0,B23-$B$6))
A24: 12 | C24: Knull to 3 red stars | D24: 400K purple nuggets | E24: 900000 | F24: 0 | G24: 1900000 | H24: Claimed | I24: =IF(B24="","",MAX(0,B24-$B$6))
A25: 13 | C25: Professor Xavier to 3 red stars | D25: 400K purple nuggets | E25: 0 | F25: 1300000 | G25: 1900000 | H25: Claimed | I25: =IF(B25="","",MAX(0,B25-$B$6))
A26: 14 | C26: Maestro to 3 red stars | D26: 400K purple nuggets | E26: 900000 | F26: 1300000 | G26: 0 | H26: Claimed | I26: =IF(B26="","",MAX(0,B26-$B$6))
A27: 15 | B27: 300000000 | D27: 400K purple nuggets | E27: 900000 | F27: 1300000 | G27: 1900000 | H27: Claimed | I27: =IF(B27="","",MAX(0,B27-$B$6)) -> 0
A28: 16 | B28: 325000000 | C28: Knull to 4 red stars | D28: 400K purple nuggets | E28: 950000 | F28: 0 | G28: 1900000 | H28: Claimed | I28: =IF(B28="","",MAX(0,B28-$B$6)) -> 0
A29: 17 | B29: 350000000 | C29: Professor Xavier to 4 red stars | D29: 400K purple nuggets | E29: 0 | F29: 1400000 | G29: 1900000 | H29: Not claimed | I29: =IF(B29="","",MAX(0,B29-$B$6)) -> 19846005
A30: 18 | B30: 375000000 | C30: Maestro to 4 red stars | D30: Amounts cut off | H30: Not claimed | I30: =IF(B30="","",MAX(0,B30-$B$6)) -> 44846005
A31: 19 | B31: 400000000 | C31: Knull to 5 red stars | D31: 400K purple nuggets | E31: 0 | F31: 1400000 | G31: 1900000 | H31: Not claimed | I31: =IF(B31="","",MAX(0,B31-$B$6)) -> 69846005
A32: 20 | B32: 425000000 | C32: Professor Xavier to 5 red stars | E32: 1300000 | F32: 1400000 | G32: 1900000 | H32: Not claimed | I32: =IF(B32="","",MAX(0,B32-$B$6)) -> 94846005
A33: 21 | B33: 450000000 | C33: Maestro to 5 red stars | D33: 400K purple nuggets | E33: 0 | F33: 1400000 | G33: 1900000 | H33: Not claimed | I33: =IF(B33="","",MAX(0,B33-$B$6)) -> 119846005
A34: 22 | B34: 475000000 | C34: Knull to 6 red stars | E34: 1300000 | F34: 1400000 | G34: 1900000 | H34: Not claimed | I34: =IF(B34="","",MAX(0,B34-$B$6)) -> 144846005
A35: 23 | B35: 500000000 | C35: Professor Xavier to 6 red stars | D35: 400K purple nuggets | E35: 0 | F35: 1400000 | G35: 1900000 | H35: Not claimed | I35: =IF(B35="","",MAX(0,B35-$B$6)) -> 169846005
A36: 24 | B36: 525000000 | C36: Maestro to 6 red stars | E36: 1300000 | F36: 1400000 | G36: 1900000 | H36: Not claimed | I36: =IF(B36="","",MAX(0,B36-$B$6)) -> 194846005
A37: 25 | B37: 550000000 | C37: Knull to 7 red stars | D37: 400K purple nuggets | E37: 0 | F37: 1400000 | G37: 1900000 | H37: Not claimed | I37: =IF(B37="","",MAX(0,B37-$B$6)) -> 219846005
A38: 26 | B38: 600000000 | C38: Professor Xavier to 7 red stars | E38: 1300000 | F38: 1400000 | G38: 2000000 | H38: Not claimed | I38: =IF(B38="","",MAX(0,B38-$B$6)) -> 269846005
A39: 27 | B39: 650000000 | C39: Maestro to 7 red stars | D39: 400K purple nuggets | E39: 0 | F39: 1400000 | G39: 2000000 | H39: Not claimed | I39: =IF(B39="","",MAX(0,B39-$B$6)) -> 319846005
A40: 28 | B40: 750000000 | C40: Spider-Man (Superior) Diamond 1 | E40: 1300000 | F40: 1400000 | G40: 2000000 | H40: Not claimed | I40: =IF(B40="","",MAX(0,B40-$B$6)) -> 419846005
A41: 29 | B41: 900000000 | C41: Knull Diamond 1 | D41: 400K purple nuggets | E41: 0 | F41: 1400000 | G41: 2000000 | H41: Not claimed | I41: =IF(B41="","",MAX(0,B41-$B$6)) -> 569846005
...
