Workbook

Sheet Iso Fest
A1: Iso Fest Milestones
A2: Update Current points and set each Status from its dropdown. Ion columns follow the order on the Iso-8 screen, left to right. Data from your screenshots on Oct 11, 2026.
A4: Scoring | B4: Earn 5-Diamond Professor Xavier | D4: Purple ions still to claim
A5: Ends (approx.) | B5: 46313.708 | E5: Ion 1 | F5: Ion 2 | G5: Ion 3
A6: Current points | B6: 488127315 | D6: Up to target milestone | E6: =SUMPRODUCT((A13:A54<=$B$9)*(H13:H54<>"Claimed")*E13:E54) -> 2600000 | F6: =SUMPRODUCT((A13:A54<=$B$9)*(H13:H54<>"Claimed")*F13:F54) -> 5600000 | G6: =SUMPRODUCT((A13:A54<=$B$9)*(H13:H54<>"Claimed")*G13:G54) -> 7700000
A7: Next milestone | B7: =IFERROR(INDEX(A13:A54,MATCH(TRUE(),INDEX(B13:B54>B6,0),0)),"All done") -> 23 | D7: Ready to claim now | E7: =SUMPRODUCT((B13:B54<>"")*(B13:B54<=$B$6)*(H13:H54<>"Claimed")*E13:E54) -> 0 | F7: =SUMPRODUCT((B13:B54<>"")*(B13:B54<=$B$6)*(H13:H54<>"Claimed")*F13:F54) -> 0 | G7: =SUMPRODUCT((B13:B54<>"")*(B13:B54<=$B$6)*(H13:H54<>"Claimed")*G13:G54) -> 0
A8: Points to next | B8: =IFERROR(INDEX(I13:I54,MATCH(TRUE(),INDEX(B13:B54>B6,0),0)),0) -> 11872685
A9: Target milestone | B9: 26 | D9: Projected with planned spending | G9: =Scoring!B36 -> 500667315
A10: Points to target | B10: =MAX(0,INDEX(B13:B54,B9)-B6) -> 111872685 | D10: Highest milestone that reaches | G10: =Scoring!B37 -> 23
A11: Points per day for target | B11: =IFERROR(B10/MAX(B5-NOW(),0.01),0) -> 26513225
A12: Milestone | B12: Points needed | C12: Character reward | D12: Other reward | E12: Ion 1 | F12: Ion 2 | G12: Ion 3 | H12: Status | I12: Points to go
A13: 1 | D13: 200K blue, 800K green nuggets | E13: 0 | F13: 0 | G13: 0 | H13: Claimed | I13: =IF(B13="","",MAX(0,B13-$B$6))
A14: 2 | D14: 600K blue nuggets | E14: 0 | F14: 0 | G14: 0 | H14: Claimed | I14: =IF(B14="","",MAX(0,B14-$B$6))
A15: 3 | D15: 400K blue nuggets; 1M, 1M, 1.72M blue ions | E15: 0 | F15: 0 | G15: 0 | H15: Claimed | I15: =IF(B15="","",MAX(0,B15-$B$6))
A16: 4 | D16: 400K blue nuggets; 1M, 1M, 1.72M blue ions | E16: 0 | F16: 0 | G16: 0 | H16: Claimed | I16: =IF(B16="","",MAX(0,B16-$B$6))
A17: 5 | C17: Knull to 1 red star | D17: 1M, 1M blue ions; 400K blue nuggets | E17: 0 | F17: 0 | G17: 0 | H17: Claimed | I17: =IF(B17="","",MAX(0,B17-$B$6))
A18: 6 | C18: Professor Xavier to 1 red star | D18: 1M, 1M, 3.45M blue ions | E18: 0 | F18: 0 | G18: 0 | H18: Claimed | I18: =IF(B18="","",MAX(0,B18-$B$6))
A19: 7 | C19: Maestro to 1 red star | D19: 2M, 1M blue ions; 450K blue nuggets | E19: 0 | F19: 0 | G19: 0 | H19: Claimed | I19: =IF(B19="","",MAX(0,B19-$B$6))
A20: 8 | C20: Knull to 2 red stars | D20: 2M, 1M, 3.45M blue ions | E20: 0 | F20: 0 | G20: 0 | H20: Claimed | I20: =IF(B20="","",MAX(0,B20-$B$6))
A21: 9 | C21: Professor Xavier to 2 red stars | D21: 2M, 2M, 3.45M blue ions | E21: 0 | F21: 0 | G21: 0 | H21: Claimed | I21: =IF(B21="","",MAX(0,B21-$B$6))
A22: 10 | C22: Maestro to 2 red stars | D22: 1 item; 2M, 3.45M blue ions | E22: 0 | F22: 0 | G22: 0 | H22: Claimed | I22: =IF(B22="","",MAX(0,B22-$B$6))
A23: 11 | D23: 100K purple nuggets | E23: 900000 | F23: 1300000 | G23: 1900000 | H23: Claimed | I23: =IF(B23="","",MAX(0,B23-$B$6))
A24: 12 | C24: Knull to 3 red stars | D24: 400K purple nuggets | E24: 900000 | F24: 0 | G24: 1900000 | H24: Claimed | I24: =IF(B24="","",MAX(0,B24-$B$6))
A25: 13 | C25: Professor Xavier to 3 red stars | D25: 400K purple nuggets | E25: 0 | F25: 1300000 | G25: 1900000 | H25: Claimed | I25: =IF(B25="","",MAX(0,B25-$B$6))
A26: 14 | C26: Maestro to 3 red stars | D26: 400K purple nuggets | E26: 900000 | F26: 1300000 | G26: 0 | H26: Claimed | I26: =IF(B26="","",MAX(0,B26-$B$6))
A27: 15 | B27: 300000000 | D27: 400K purple nuggets | E27: 900000 | F27: 1300000 | G27: 1900000 | H27: Claimed | I27: =IF(B27="","",MAX(0,B27-$B$6)) -> 0
A28: 16 | B28: 325000000 | C28: Knull to 4 red stars | D28: 400K purple nuggets | E28: 950000 | F28: 0 | G28: 1900000 | H28: Claimed | I28: =IF(B28="","",MAX(0,B28-$B$6)) -> 0
A29: 17 | B29: 350000000 | C29: Professor Xavier to 4 red stars | D29: 400K purple nuggets | E29: 0 | F29: 1400000 | G29: 1900000 | H29: Claimed | I29: =IF(B29="","",MAX(0,B29-$B$6)) -> 0
A30: 18 | B30: 375000000 | C30: Maestro to 4 red stars | D30: Amounts cut off | H30: Claimed | I30: =IF(B30="","",MAX(0,B30-$B$6)) -> 0
A31: 19 | B31: 400000000 | C31: Knull to 5 red stars | D31: 400K purple nuggets | E31: 0 | F31: 1400000 | G31: 1900000 | H31: Claimed | I31: =IF(B31="","",MAX(0,B31-$B$6)) -> 0
A32: 20 | B32: 425000000 | C32: Professor Xavier to 5 red stars | E32: 1300000 | F32: 1400000 | G32: 1900000 | H32: Claimed | I32: =IF(B32="","",MAX(0,B32-$B$6)) -> 0
A33: 21 | B33: 450000000 | C33: Maestro to 5 red stars | D33: 400K purple nuggets | E33: 0 | F33: 1400000 | G33: 1900000 | H33: Claimed | I33: =IF(B33="","",MAX(0,B33-$B$6)) -> 0
A34: 22 | B34: 475000000 | C34: Knull to 6 red stars | E34: 1300000 | F34: 1400000 | G34: 1900000 | H34: Claimed | I34: =IF(B34="","",MAX(0,B34-$B$6)) -> 0
A35: 23 | B35: 500000000 | C35: Professor Xavier to 6 red stars | D35: 400K purple nuggets | E35: 0 | F35: 1400000 | G35: 1900000 | H35: Not claimed | I35: =IF(B35="","",MAX(0,B35-$B$6)) -> 11872685
A36: 24 | B36: 525000000 | C36: Maestro to 6 red stars | E36: 1300000 | F36: 1400000 | G36: 1900000 | H36: Not claimed | I36: =IF(B36="","",MAX(0,B36-$B$6)) -> 36872685
A37: 25 | B37: 550000000 | C37: Knull to 7 red stars | D37: 400K purple nuggets | E37: 0 | F37: 1400000 | G37: 1900000 | H37: Not claimed | I37: =IF(B37="","",MAX(0,B37-$B$6)) -> 61872685
A38: 26 | B38: 600000000 | C38: Professor Xavier to 7 red stars | E38: 1300000 | F38: 1400000 | G38: 2000000 | H38: Not claimed | I38: =IF(B38="","",MAX(0,B38-$B$6)) -> 111872685
A39: 27 | B39: 650000000 | C39: Maestro to 7 red stars | D39: 400K purple nuggets | E39: 0 | F39: 1400000 | G39: 2000000 | H39: Not claimed | I39: =IF(B39="","",MAX(0,B39-$B$6)) -> 161872685
A40: 28 | B40: 750000000 | C40: Spider-Man (Superior) Diamond 1 | E40: 1300000 | F40: 1400000 | G40: 2000000 | H40: Not claimed | I40: =IF(B40="","",MAX(0,B40-$B$6)) -> 261872685
A41: 29 | B41: 900000000 | C41: Knull Diamond 1 | D41: 400K purple nuggets | E41: 0 | F41: 1400000 | G41: 2000000 | H41: Not claimed | I41: =IF(B41="","",MAX(0,B41-$B$6)) -> 411872685
...

Sheet Scoring
A1: Iso Fest: how to earn points
A2: Fill Earned and Limit from the event info screen. Put what you plan to spend in Planned amount, and the summary shows where that gets you.
A4: Type | B4: Task | C4: Points each | D4: Limit | E4: Earned | F4: Points left | G4: Planned amount | H4: Planned points | I4: Notes
A5: Daily | B5: Log in | C5: 3000000 | D5: 51000000 | E5: 39000000 | F5: =IF(ISNUMBER(D5),MAX(0,D5-N(E5)),"") -> 12000000 | H5: =IF(ISNUMBER(D5),MIN(N(G5)*N(C5),N(F5)),N(G5)*N(C5)) -> 0 | I5: Once a day
A6: Spend | B6: Spend Gold | C6: 1 | D6: 500000000 | E6: 158825315 | F6: =IF(ISNUMBER(D6),MAX(0,D6-N(E6)),"") -> 341174685 | G6: 7540000 | H6: =IF(ISNUMBER(D6),MIN(N(G6)*N(C6),N(F6)),N(G6)*N(C6)) -> 7540000 | I6: Planned is current gold plus the Thu and Sun Gold Rushes
A7: Spend | B7: Spend Power Cores | C7: 1000 | D7: 250000000 | E7: 10300000 | F7: =IF(ISNUMBER(D7),MAX(0,D7-N(E7)),"") -> 239700000 | H7: =IF(ISNUMBER(D7),MIN(N(G7)*N(C7),N(F7)),N(G7)*N(C7)) -> 0 | I7: Includes cores spent before Iron Vengeance began
A8: Spend | B8: Spend L4 Training Modules (orange) | C8: 5000 | D8: 500000000 | E8: 58180000 | F8: =IF(ISNUMBER(D8),MAX(0,D8-N(E8)),"") -> 441820000 | H8: =IF(ISNUMBER(D8),MIN(N(G8)*N(C8),N(F8)),N(G8)*N(C8)) -> 0
A9: Ions | B9: Spend 1 Tier 2 Level 5 Ion | C9: 1 | D9: 88000000 | E9: 11025000 | F9: =IF(ISNUMBER(D9),MAX(0,D9-N(E9)),"") -> 76975000 | H9: =IF(ISNUMBER(D9),MIN(N(G9)*N(C9),N(F9)),N(G9)*N(C9)) -> 0
A10: Ions | B10: Spend 1 Tier 2 Level 4 Ion | C10: 1 | D10: 50000000 | E10: 7400000 | F10: =IF(ISNUMBER(D10),MAX(0,D10-N(E10)),"") -> 42600000 | H10: =IF(ISNUMBER(D10),MIN(N(G10)*N(C10),N(F10)),N(G10)*N(C10)) -> 0
A11: Ions | B11: Spend 1 Tier 2 Level 1 Ion | C11: 1 | D11: 50000000 | E11: 7401500 | F11: =IF(ISNUMBER(D11),MAX(0,D11-N(E11)),"") -> 42598500 | H11: =IF(ISNUMBER(D11),MIN(N(G11)*N(C11),N(F11)),N(G11)*N(C11)) -> 0
A12: Ions | B12: Spend 1 Tier 3 Level 5 Ion | C12: 1 | F12: =IF(ISNUMBER(D12),MAX(0,D12-N(E12)),"") | H12: =IF(ISNUMBER(D12),MIN(N(G12)*N(C12),N(F12)),N(G12)*N(C12)) -> 0 | I12: Unlimited. Game doesn't show earned
A13: Ions | B13: Spend 1 Tier 3 Level 4 Ion | C13: 1 | F13: =IF(ISNUMBER(D13),MAX(0,D13-N(E13)),"") | H13: =IF(ISNUMBER(D13),MIN(N(G13)*N(C13),N(F13)),N(G13)*N(C13)) -> 0 | I13: Unlimited. Game doesn't show earned
A14: Ions | B14: Spend 1 Tier 3 Level 1 Ion | C14: 1 | F14: =IF(ISNUMBER(D14),MAX(0,D14-N(E14)),"") | H14: =IF(ISNUMBER(D14),MIN(N(G14)*N(C14),N(F14)),N(G14)*N(C14)) -> 0 | I14: Unlimited. Game doesn't show earned
A15: Ions | B15: Spend 1 Tier 4 Level 1 Ion | C15: 1 | F15: =IF(ISNUMBER(D15),MAX(0,D15-N(E15)),"") | H15: =IF(ISNUMBER(D15),MIN(N(G15)*N(C15),N(F15)),N(G15)*N(C15)) -> 0 | I15: Unlimited. Game doesn't show earned
A16: Upgrade | B16: Insidious Six to T3 L4 | C16: 2000000 | D16: 6000000 | E16: 6000000 | F16: =IF(ISNUMBER(D16),MAX(0,D16-N(E16)),"") -> 0 | H16: =IF(ISNUMBER(D16),MIN(N(G16)*N(C16),N(F16)),N(G16)*N(C16)) -> 0 | I16: Planned is number of upgrades
A17: Upgrade | B17: Insidious Six to T3 L5 | C17: 3000000 | D17: 9000000 | E17: 6000000 | F17: =IF(ISNUMBER(D17),MAX(0,D17-N(E17)),"") -> 3000000 | H17: =IF(ISNUMBER(D17),MIN(N(G17)*N(C17),N(F17)),N(G17)*N(C17)) -> 0 | I17: Planned is number of upgrades
A18: Upgrade | B18: Symbiote Six to T3 L4 | C18: 2000000 | D18: 10000000 | E18: 10000000 | F18: =IF(ISNUMBER(D18),MAX(0,D18-N(E18)),"") -> 0 | H18: =IF(ISNUMBER(D18),MIN(N(G18)*N(C18),N(F18)),N(G18)*N(C18)) -> 0 | I18: Planned is number of upgrades
A19: Upgrade | B19: Symbiote Six to T3 L5 | C19: 3000000 | D19: 15000000 | E19: 0 | F19: =IF(ISNUMBER(D19),MAX(0,D19-N(E19)),"") -> 15000000 | H19: =IF(ISNUMBER(D19),MIN(N(G19)*N(C19),N(F19)),N(G19)*N(C19)) -> 0 | I19: Planned is number of upgrades
A20: Upgrade | B20: Amazing Avenger to T3 L4 | C20: 2000000 | D20: 10000000 | E20: 10000000 | F20: =IF(ISNUMBER(D20),MAX(0,D20-N(E20)),"") -> 0 | H20: =IF(ISNUMBER(D20),MIN(N(G20)*N(C20),N(F20)),N(G20)*N(C20)) -> 0 | I20: Planned is number of upgrades
A21: Upgrade | B21: Amazing Avenger to T3 L5 | C21: 3000000 | D21: 15000000 | E21: 15000000 | F21: =IF(ISNUMBER(D21),MAX(0,D21-N(E21)),"") -> 0 | H21: =IF(ISNUMBER(D21),MIN(N(G21)*N(C21),N(F21)),N(G21)*N(C21)) -> 0 | I21: Planned is number of upgrades
A22: Upgrade | B22: Cosmic character to T3 L5 | C22: 5000000 | D22: 25000000 | E22: 20000000 | F22: =IF(ISNUMBER(D22),MAX(0,D22-N(E22)),"") -> 5000000 | G22: 1 | H22: =IF(ISNUMBER(D22),MIN(N(G22)*N(C22),N(F22)),N(G22)*N(C22)) -> 5000000 | I22: Mephisto planned after milestone 24
A23: Upgrade | B23: Global character to T3 L5 | C23: 5000000 | D23: 25000000 | E23: 15000000 | F23: =IF(ISNUMBER(D23),MAX(0,D23-N(E23)),"") -> 10000000 | H23: =IF(ISNUMBER(D23),MIN(N(G23)*N(C23),N(F23)),N(G23)*N(C23)) -> 0 | I23: Planned is number of upgrades
A24: Upgrade | B24: City character to T3 L5 | C24: 5000000 | D24: 25000000 | E24: 25000000 | F24: =IF(ISNUMBER(D24),MAX(0,D24-N(E24)),"") -> 0 | H24: =IF(ISNUMBER(D24),MIN(N(G24)*N(C24),N(F24)),N(G24)*N(C24)) -> 0 | I24: Planned is number of upgrades
A25: Upgrade | B25: Cosmic character to T4 L3 | C25: 8000000 | D25: 40000000 | E25: 0 | F25: =IF(ISNUMBER(D25),MAX(0,D25-N(E25)),"") -> 40000000 | H25: =IF(ISNUMBER(D25),MIN(N(G25)*N(C25),N(F25)),N(G25)*N(C25)) -> 0 | I25: Planned is number of upgrades
A26: Upgrade | B26: Global character to T4 L3 | C26: 8000000 | D26: 40000000 | E26: 0 | F26: =IF(ISNUMBER(D26),MAX(0,D26-N(E26)),"") -> 40000000 | H26: =IF(ISNUMBER(D26),MIN(N(G26)*N(C26),N(F26)),N(G26)*N(C26)) -> 0 | I26: Planned is number of upgrades
A27: Upgrade | B27: City character to T4 L3 | C27: 8000000 | D27: 40000000 | E27: 0 | F27: =IF(ISNUMBER(D27),MAX(0,D27-N(E27)),"") -> 40000000 | H27: =IF(ISNUMBER(D27),MIN(N(G27)*N(C27),N(F27)),N(G27)*N(C27)) -> 0 | I27: Planned is number of upgrades
A28: Offers | B28: Earn Iso Fest milestone points in select offers | C28: 1 | F28: =IF(ISNUMBER(D28),MAX(0,D28-N(E28)),"") | H28: =IF(ISNUMBER(D28),MIN(N(G28)*N(C28),N(F28)),N(G28)*N(C28)) -> 0 | I28: Unlimited
F29: =IF(ISNUMBER(D29),MAX(0,D29-N(E29)),"") | H29: =IF(ISNUMBER(D29),MIN(N(G29)*N(C29),N(F29)),N(G29)*N(C29)) -> 0 | I29: Spare row
F30: =IF(ISNUMBER(D30),MAX(0,D30-N(E30)),"") | H30: =IF(ISNUMBER(D30),MIN(N(G30)*N(C30),N(F30)),N(G30)*N(C30)) -> 0 | I30: Spare row
A32: Earned from tasks with a limit | B32: =SUM(E5:E30) -> 399131815
A33: Unlimited tasks, ions and offers | B33: ='Iso Fest'!B6-B32 -> 88995500
A34: Current points | B34: ='Iso Fest'!B6 -> 488127315
A35: Points from planned spending | B35: =SUM(H5:H30) -> 12540000
A36: Projected total | B36: =B34+B35 -> 500667315
A37: Highest milestone reached | B37: =IFERROR(INDEX('Iso Fest'!A13:A54,MATCH(B36,'Iso Fest'!B13:B54,1)),"Below milestone 15") -> 23
A38: Points short of target | B38: =MAX(0,INDEX('Iso Fest'!B13:B54,'Iso Fest'!B9)-B36) -> 99332685
A40: Target milestone is set on the Iso Fest tab. Limit blank means no limit.
